Workbook

Sheet 保费基数核对表
A1: 附5
A2: 保费基数核对表
A3: 投保机构： | F3: 单位：元
A4: 顺序 | B4: 行列名称 | C4: 存款归属核对 | F4: 会计科目核对 | M4: 被保险存款申报表（IRP001） | P4: 差额说明
C5: 子项代码 | E5: 根据金融机构资产负债项目月报表（A1411、A2411） | F5: 本金 | I5: 利息 | L5: 合计 | M5: 本金 | N5: 利息 | O5: 合计
E6: 本金 | F6: 代码 | G6: 科目名称 | H6: 金额 | I6: 代码 | J6: 科目名称 | K6: 金额
A7: 1 | B7: 一、境内存款 | D7: （一）个人存款 | E7: =E14-SUM(E20:E28)+E29 -> 0 | G7: （一）个人存款 | H7: =SUM(H14:H18) -> 0 | J7: （一）个人存款应付利息 | K7: =SUM(K14:K17) -> 0 | L7: =H7+K7 -> 0 | O7: =M7+N7 -> 0
D8: （二）单位存款 | E8: =E30-SUM(E36:E43)+E44-E47+SUM(E48:E53) -> 0 | G8: （二）单位存款 | H8: =SUM(H30:H35)+H44 -> 0 | J8: （二）单位存款应付利息 | K8: =SUM(K30:K35) -> 0 | L8: =H8+K8 -> 0 | O8: =M8+N8 -> 0
D9: 其中：住房公积金存款 | E9: =SUM(E54:E62) -> 0 | G9: （三）财政性存款 | H9: =SUM(H74:H78) -> 0 | J9: （三）财政性存款应付利息 | K9: =SUM(K74:K78) -> 0 | L9: =H9+K9 -> 0 | O9: =M9+N9 -> 0
D10: 社保基金存款 | E10: =SUM(E63:E71) -> 0 | G10: （四）非存款类金融机构存款 | H10: =H81+H85 -> 0 | J10: （四）非存款类金融机构存款应付利息 | K10: =K81+K85 -> 0 | L10: =H10+K10 -> 0 | O10: =M10+N10 -> 0
D11: （三）财政性存款 | E11: =E74+E75+E76 -> 0 | G11: 三、高级管理人员在本机构存款 | H11: =H124 -> 0 | J11: 三、高级管理人员在本机构存款利息 | K11: =K124 -> 0 | L11: =H11+K11 -> 0 | O11: =M11+N11 -> 0
D12: （四）非存款类金融机构存款 | E12: =SUM(E79:E97) -> 0 | G12: 四、不予保险的其他存款 | H12: =H125 -> 0 | J12: 四、不予保险的其他存款利息 | K12: =K125 -> 0 | L12: =H12+K12 -> 0 | O12: =M12+N12 -> 0
D13: 境内存款合计 | E13: =E7+E8+E11+E12 -> 0 | G13: 被保险存款合计 | H13: =H7+H8+H9-H11-H12 -> 0 | J13: 被保险存款利息合计 | K13: =K7+K8+K9-K11-K12 -> 0 | L13: =H13+K13 -> 0 | M13: =M7+M8+M9-M11-M12 -> 0 | N13: =N7+N8+N9-N11-N12 -> 0 | O13: =M13+N13 -> 0
A14: 2 | B14: ( 一) 个人存款 | C14: 12MI1/22MI1 | D14: 2.个人存款 | F14: 2003 | G14: 个人活期存款 | I14: 223103 | J14: 个人活期存款应付利息
F15: 2004 | G15: 个人定期存款 | I15: 223104 | J15: 个人定期存款应付利息
F16: 200503 | G16: 个人银行卡活期存款 | I16: 22310503 | J16: 个人银行卡活期存款应付利息
F17: 200504 | G17: 个人银行卡定期存款 | I17: 22310504 | J17: 个人银行卡定期存款应付利息
F18: 20140102 | G18: 保证金存款(个人部分） | I18: 223108 | J18: 保证金存款应付利息(个人部分)
C20: 12MI3/22MI3 | D20: 其中： 非居民
C21: 12MI5/22MI5 | D21: 其中： 非居民
C22: 12MI7/22MI7 | D22: 其中： 非居民
C23: 12MI9/22MI9 | D23: 其中： 非居民
C24: 12MIB/22MIB | D24: 其中： 非居民
C25: 12MID/22MID | D25: 其中： 非居民
C26: 12MIF/22MIF | D26: 其中： 非居民
C27: 12MIH/22MIH | D27: 其中： 非居民
C28: 12N1A/22N1A | D28: 其中： 非居民
C29: 12MW5/22MW5 | D29: 境内个人
A30: 3 | B30: ( 二) 单位存款 | C30: 12MG3/22MG3 | D30: 1.单位存款 | F30: 2001 | G30: 单位活期存款 | I30: 223101 | J30: 单位活期存款应付利息
F31: 2002 | G31: 单位定期存款 | I31: 223102 | J31: 单位定期存款应付利息
F32: 200501 | G32: 单位银行卡活期存款 | I32: 22310501 | J32: 单位银行卡活期存款应付利息
F33: 200502 | G33: 单位银行卡定期存款 | I33: 22310502 | J33: 单位银行卡定期存款应付利息
F34: 200601 | G34: 财政性存款 | I34: 22310601 | J34: 财政性存款应付利息
F35: 20140101 | G35: 保证金存款（单位部分） | I35: 223108 | J35: 保证金存款应付利息(单位部分)
C36: 12MGA/22MGA | D36: 非居民活期存款
C37: 12MGH/22MGH | D37: 非居民定期存款
C38: 12MGQ/22MGQ | D38: 非居民通知存款
C39: 12MH3/22MH3 | D39: 非居民协议存款
C40: 12MHA/22MHA | D40: 非居民协定存款
C41: 12MHH/22MHH | D41: 非居民保证金存款
...

Sheet 校验
B1: 存款归属统计表与IRP001核对 | C1: 差额 | D1: 会计科目与IRP001核对
A2: 项目名称 | B2: 本金 | D2: 本金 | E2: 利息 | F2: 合计
A3: （一）个人存款 | B3: =IF(保费基数核对表!E7=ROUND((保费基数核对表!M7-保费基数核对表!P9)/10000,0),0,1) -> 0 | C3: =保费基数核对表!E7-ROUND((保费基数核对表!M7-保费基数核对表!P9)/10000,0) -> 0 | D3: =IF(保费基数核对表!H7=保费基数核对表!M7,0,1) -> 0 | E3: =IF(保费基数核对表!K7=保费基数核对表!N7,0,1) -> 0 | F3: =IF(保费基数核对表!L7=保费基数核对表!O7,0,1) -> 0
A4: （二）单位存款 | B4: =IF(保费基数核对表!E8=ROUND((保费基数核对表!M8-保费基数核对表!P10)/10000,0),0,1) -> 0 | C4: =保费基数核对表!E8-ROUND((保费基数核对表!M8-保费基数核对表!P10)/10000,0) -> 0 | D4: =IF(保费基数核对表!H8=保费基数核对表!M8,0,1) -> 0 | E4: =IF(保费基数核对表!K8=保费基数核对表!N8,0,1) -> 0 | F4: =IF(保费基数核对表!L8=保费基数核对表!O8,0,1) -> 0
A5: （三）财政性存款 | B5: =IF(保费基数核对表!E11=ROUND(保费基数核对表!M9/10000,0),0,1) -> 0 | C5: =保费基数核对表!E11-ROUND(保费基数核对表!M9/10000,0) -> 0 | D5: =IF(保费基数核对表!H9=保费基数核对表!M9,0,1) -> 0 | E5: =IF(保费基数核对表!K9=保费基数核对表!N9,0,1) -> 0 | F5: =IF(保费基数核对表!L9=保费基数核对表!O9,0,1) -> 0
A6: （四）非存款类金融机构存款 | B6: =保费基数核对表!E12-ROUND(保费基数核对表!M10/10000,0) -> 0 | C6: =保费基数核对表!E12-ROUND(保费基数核对表!M10/10000,0) -> 0 | D6: =IF(保费基数核对表!H10=保费基数核对表!M10,0,1) -> 0 | E6: =IF(保费基数核对表!K10=保费基数核对表!N10,0,1) -> 0 | F6: =IF(保费基数核对表!L10=保费基数核对表!O10,0,1) -> 0
A7: 三、高级管理人员在本机构存款 | B7: / | D7: =IF(保费基数核对表!H11=保费基数核对表!M11,0,1) -> 0 | E7: =IF(保费基数核对表!K11=保费基数核对表!N11,0,1) -> 0 | F7: =IF(保费基数核对表!L11=保费基数核对表!O11,0,1) -> 0
A8: 四、不予保险的其他存款 | B8: / | D8: =IF(保费基数核对表!H12=保费基数核对表!M12,0,1) -> 0 | E8: =IF(保费基数核对表!K12=保费基数核对表!N12,0,1) -> 0 | F8: =IF(保费基数核对表!L12=保费基数核对表!O12,0,1) -> 0
A9: 被保险存款合计 | B9: / | D9: =IF(保费基数核对表!H13=保费基数核对表!M13,0,1) -> 0 | E9: =IF(保费基数核对表!K13=保费基数核对表!N13,0,1) -> 0 | F9: =IF(保费基数核对表!L13=保费基数核对表!O13,0,1) -> 0
